2024-03-19 13:13:56,470 ERROR Internal Server Error: /news/news/create/ C:\Users\dasha\Project_Skillfactory_module_D\D2_NewsPortal\newsportal\news_venv\lib\site-packages\django\utils\log.py (<class 'django.template.exceptions.TemplateDoesNotExist'>, TemplateDoesNotExist('post_edt.html'), <traceback object at 0x054D2188>)
Traceback (most recent call last):
  File "C:\Users\dasha\Project_Skillfactory_module_D\D2_NewsPortal\newsportal\news_venv\lib\site-packages\django\core\handlers\exception.py", line 55, in inner
    response = get_response(request)
  File "C:\Users\dasha\Project_Skillfactory_module_D\D2_NewsPortal\newsportal\news_venv\lib\site-packages\django\core\handlers\base.py", line 220, in _get_response
    response = response.render()
  File "C:\Users\dasha\Project_Skillfactory_module_D\D2_NewsPortal\newsportal\news_venv\lib\site-packages\django\template\response.py", line 114, in render
    self.content = self.rendered_content
  File "C:\Users\dasha\Project_Skillfactory_module_D\D2_NewsPortal\newsportal\news_venv\lib\site-packages\django\template\response.py", line 90, in rendered_content
    template = self.resolve_template(self.template_name)
  File "C:\Users\dasha\Project_Skillfactory_module_D\D2_NewsPortal\newsportal\news_venv\lib\site-packages\django\template\response.py", line 72, in resolve_template
    return select_template(template, using=self.using)
  File "C:\Users\dasha\Project_Skillfactory_module_D\D2_NewsPortal\newsportal\news_venv\lib\site-packages\django\template\loader.py", line 47, in select_template
    raise TemplateDoesNotExist(", ".join(template_name_list), chain=chain)
django.template.exceptions.TemplateDoesNotExist: post_edt.html
2024-03-19 13:13:56,478 ERROR "GET /news/news/create/ HTTP/1.1" 500 89069 C:\Users\dasha\Project_Skillfactory_module_D\D2_NewsPortal\newsportal\news_venv\lib\site-packages\django\core\servers\basehttp.py None
